<robot
  name="lrmate_200id_description">
  <link
    name="base_link">
    <inertial>
      <origin
        xyz="-0.00682671502006336 -0.000321708237365649 0.0804229485104674"
        rpy="0 0 0" />
      <mass
        value="6.28702953522501" />
      <inertia
        ixx="0.028482"
        ixy="0.000154"
        ixz="-0.000185"
        iyy="0.030869"
        iyz="0.000040"
        izz="0.029537" />
    </inertial>
    <visual>
      <origin
        xyz="0 0 0"
        rpy="0 0 0" />
      <geometry>
        <mesh
          filename="package://lrmate_200id_description/meshes/base_link.STL" />
      </geometry>
      <material
        name="">
        <color
          rgba="0 0 0 1" />
      </material>
    </visual>
    <collision>
      <origin
        xyz="0 0 0"
        rpy="0 0 0" />
      <geometry>
        <mesh
          filename="package://lrmate_200id_description/meshes/base_link_collision.STL" />
      </geometry>
    </collision>
  </link>
  <link
    name="shoulder">
    <inertial>
      <origin
        xyz="0.0172172318737863 -0.000437365526737111 0.0775885743652039"
        rpy="0 0 0" />
      <mass
        value="4.13202512738557" />
      <inertia
        ixx="0.03754"
        ixy="0"
        ixz="0.00442"
        iyy="0.02132"
        iyz="-0.00003"
        izz="0.03020" />
    </inertial>
    <visual>
      <origin
        xyz="0 0 0"
        rpy="0 0 0" />
      <geometry>
        <mesh
          filename="package://lrmate_200id_description/meshes/shoulder.STL" />
      </geometry>
      <material
        name="">
        <color
          rgba="1 1 0 1" />
      </material>
    </visual>
    <collision>
      <origin
        xyz="0 0 0"
        rpy="0 0 0" />
      <geometry>
        <mesh
          filename="package://lrmate_200id_description/meshes/shoulder_collision.STL" />
      </geometry>
    </collision>
  </link>
  <joint
    name="shoulder_yaw"
    type="revolute">
    <origin
      xyz="0 8.69401445555014E-05 0.17"
      rpy="0 0 0" />
    <parent
      link="base_link" />
    <child
      link="shoulder" />
    <axis
      xyz="0 0 1" />
    <limit
      lower="-2.967059728"
      upper="2.967059728"
      effort="135"
      velocity="8.028518" />
  </joint>
  <link
    name="bicep">
    <inertial>
      <origin
        xyz="-0.00799366591442193 -0.00180217948175914 0.121255504698164"
        rpy="0 0 0" />
      <mass
        value="8.24093772313152" />
      <inertia
        ixx="0.13816"
        ixy="-0.00011"
        ixz="-0.00188"
        iyy="0.11279"
        iyz="0.00072"
        izz="0.04107" />
    </inertial>
    <visual>
      <origin
        xyz="0 0 0"
        rpy="0 0 0" />
      <geometry>
        <mesh
          filename="package://lrmate_200id_description/meshes/bicep.STL" />
      </geometry>
      <material
        name="">
        <color
          rgba="1 1 0 1" />
      </material>
    </visual>
    <collision>
      <origin
        xyz="0 0 0"
        rpy="0 0 0" />
      <geometry>
        <mesh
          filename="package://lrmate_200id_description/meshes/bicep_collision.STL" />
      </geometry>
    </collision>
  </link>
  <joint
    name="shoulder_pitch"
    type="revolute">
    <origin
      xyz="0.0499991769452175 -8.69401445554976E-05 0.16"
      rpy="0 0 0" />
    <parent
      link="shoulder" />
    <child
      link="bicep" />
    <axis
      xyz="0 1 0" />
    <limit
      lower="-1.919862177"
      upper="2.094395102"
      effort="308"
      velocity="8.028518" />
  </joint>
  <link
    name="elbow">
    <inertial>
      <origin
        xyz="0.00847543253616633 0.000678404513221338 0.0176970934206649"
        rpy="0 0 0" />
      <mass
        value="3.11070759102685" />
      <inertia
        ixx="0.00822"
        ixy="0.00006"
        ixz="0.00100"
        iyy="0.00956"
        iyz="0.00009"
        izz="0.00947" />
    </inertial>
    <visual>
      <origin
        xyz="0 0 0"
        rpy="0 0 0" />
      <geometry>
        <mesh
          filename="package://lrmate_200id_description/meshes/elbow.STL" />
      </geometry>
      <material
        name="">
        <color
          rgba="1 1 0 1" />
      </material>
    </visual>
    <collision>
      <origin
        xyz="0 0 0"
        rpy="0 0 0" />
      <geometry>
        <mesh
          filename="package://lrmate_200id_description/meshes/elbow_collision.STL" />
      </geometry>
    </collision>
  </link>
  <joint
    name="elbow_pitch"
    type="revolute">
    <origin
      xyz="0 0 0.33"
      rpy="0 0 0" />
    <parent
      link="bicep" />
    <child
      link="elbow" />
    <axis
      xyz="0 1 0" />
    <limit
      lower="-3.577924967"
      upper="1.204277184"
      effort="308"
      velocity="9.075716" />
  </joint>
  <link
    name="forearm">
    <inertial>
      <origin
        xyz="0.109857207893336 0.00425054467769336 0.000306549247326315"
        rpy="0 0 0" />
      <mass
        value="2.64233524900363" />
      <inertia
        ixx="0.00442"
        ixy="0.00022"
        ixz="-0.00002"
        iyy="0.01499"
        iyz="0.00000"
        izz="0.01550" />
    </inertial>
    <visual>
      <origin
        xyz="0 0 0"
        rpy="0 0 0" />
      <geometry>
        <mesh
          filename="package://lrmate_200id_description/meshes/forearm.STL" />
      </geometry>
      <material
        name="">
        <color
          rgba="1 1 0 1" />
      </material>
    </visual>
    <collision>
      <origin
        xyz="0 0 0"
        rpy="0 0 0" />
      <geometry>
        <mesh
          filename="package://lrmate_200id_description/meshes/forearm_collision.STL" />
      </geometry>
    </collision>
  </link>
  <joint
    name="elbow_roll"
    type="revolute">
    <origin
      xyz="0.0901 0 0.035"
      rpy="0 0 0" />
    <parent
      link="elbow" />
    <child
      link="forearm" />
    <axis
      xyz="1 0 0" />
    <limit
      lower="-3.316125579"
      upper="3.316125579"
      effort="20"
      velocity="9.773848" />
  </joint>
  <link
    name="wrist">
    <inertial>
      <origin
        xyz="0.0157332924856707 0.00307670269056515 -6.01358908385863E-05"
        rpy="0 0 0" />
      <mass
        value="0.560705873959261" />
      <inertia
        ixx="0.00038"
        ixy="-0.00003"
        ixz="0"
        iyy="0.00072"
        iyz="0"
        izz="0.00069" />
    </inertial>
    <visual>
      <origin
        xyz="0 0 0"
        rpy="0 0 0" />
      <geometry>
        <mesh
          filename="package://lrmate_200id_description/meshes/wrist.STL" />
      </geometry>
      <material
        name="">
        <color
          rgba="1 1 0 1" />
      </material>
    </visual>
    <collision>
      <origin
        xyz="0 0 0"
        rpy="0 0 0" />
      <geometry>
        <mesh
          filename="package://lrmate_200id_description/meshes/wrist_collision.STL" />
      </geometry>
    </collision>
  </link>
  <joint
    name="wrist_pitch"
    type="revolute">
    <origin
      xyz="0.2449 0 0"
      rpy="0 0 0" />
    <parent
      link="forearm" />
    <child
      link="wrist" />
    <axis
      xyz="0 1 0" />
    <limit
      lower="-2.094395102"
      upper="2.094395102"
      effort="20"
      velocity="9.773848" />
  </joint>
  <link
    name="palm">
    <inertial>
      <origin
        xyz="-0.0063856 2.7456E-19 -0.00017325"
        rpy="0 0 0" />
      <mass
        value="0.017344" />
      <inertia
        ixx="0.00000360"
        ixy="0"
        ixz="0"
        iyy="0.00000197"
        iyz="0"
        izz="0.00000202" />
    </inertial>
    <visual>
      <origin
        xyz="0 0 0"
        rpy="0 0 0" />
      <geometry>
        <mesh
          filename="package://lrmate_200id_description/meshes/palm.STL" />
      </geometry>
      <material
        name="">
        <color
          rgba="0.133333333333333 0.133333333333333 0.133333333333333 1" />
      </material>
    </visual>
    <collision>
      <origin
        xyz="0 0 0"
        rpy="0 0 0" />
      <geometry>
        <mesh
          filename="package://lrmate_200id_description/meshes/palm_collision.STL" />
      </geometry>
    </collision>
  </link>
  <joint
    name="wrist_roll"
    type="revolute">
    <origin
      xyz="0.08 0 0"
      rpy="0 0 0" />
    <parent
      link="wrist" />
    <child
      link="palm" />
    <axis
      xyz="1 0 0" />
    <limit
      lower="-6.283185307"
      upper="6.283185307"
      effort="10"
      velocity="15.70797" />
  </joint>
</robot>
